Workbook
Name polla: Hoja2!$A$4:$B$49

Sheet Hoja1
E1: PRIMERA FECHA | BY1: SEGUNDA FECHA | ES1: TERCERA FECHA | HM1: DIECISESAVOS | JI1: OCTAVOS | KG1: CUARTOS | KS1: SEMIFINALES | KY1: TERCER Y CUARTO | LB1: FINAL | LE1: CUARTO | LG1: TERCERO | LI1: SUBCAMPEÓN | LK1: CAMPEÓN | LM1: GOLEADOR
A2: JUGADORES POLLA GORETTIANA | C2: TOTAL | D2: ACIERTOS | E2: MEXICO | F2: SUDAFRICA | G2: PUNTOS | H2: COREA | I2: REP. CHECA | J2: PUNTOS | K2: CANADA | L2: BOSNIA | M2: PUNTOS | N2: USA | O2: PARAGUAY | P2: PUNTOS | Q2: QATAR | R2: SUIZA | S2: PUNTOS | T2: BRASIL | U2: MARRUECOS | V2: PUNTOS | W2: HAITI | X2: ESCOCIA | Y2: PUNTOS | Z2: AUSTRALIA | AA2: TURQUÍA | AB2: PUNTOS | AC2: ALEMANIA | AD2: CURAZAO | AE2: PUNTOS | AF2: PAISES B. | AG2: JAPÓN | AH2: PUNTOS | AI2: COSTA DE M. | AJ2: ECUADOR | AK2: PUNTOS | AL2: SUECIA | AM2: TUNEZ | AN2: PUNTOS | AO2: EPAÑA | AP2: CABO VERDE | AQ2: PUNTOS | AR2: BELGICA | AS2: EGIPTO | AT2: PUNTOS | AU2: ARABIA S. | AV2: URUGUAY | AW2: PUNTOS | AX2: IRAN | AY2: NUEVA ZELAN | AZ2: PUNTOS | BA2: FRANCIA | BB2: SENEGAL | BC2: PUNTOS | BD2: IRAK | BE2: NORUEGA | BF2: PUNTOS | BG2: ARGENTINA | BH2: ARGELIA | BI2: PUNTOS | BJ2: AUSTRIA | BK2: JORDANIA | BL2: PUNTOS | BM2: PORTUGAL | BN2: RIO CONGO | BO2: PUNTOS | BP2: INGLATERRA | BQ2: CROACIA | BR2: PUNTOS | BS2: GHANA | BT2: PANAMA | BU2: PUNTOS | BV2: UZBEKISTAN | BW2: COLOMBIA | BX2: PUNTOS | BY2: SUDAFRICA | BZ2: REP. CHECA | CA2: PUNTOS | CB2: BOSNIA | CC2: SUIZA | CD2: PUNTOS | CE2: CÁNADA | CF2: QATAR | CG2: PUNTOS | CH2: MÉXICO | CI2: COREA | CJ2: PUNTOS | CK2: USA | CL2: AUSTRALIA | CM2: PUNTOS | CN2: ESCOCIA | CO2: MARRUECOS | CP2: PUNTOS | CQ2: BRASIL | CR2: HAITI | CS2: PUNTOS | CT2: TURQUÍA | CU2: PARAGUAY | CV2: PUNTOS | CW2: PAISES BAJOS | CX2: SUECIA | CY2: PUNTOS | CZ2: ALEMANIA | DA2: COSTA DE M. | DB2: PUNTOS | DC2: ECUADOR | DD2: CURAZAO | DE2: PUNTOS | DF2: TUNEZ | DG2: JAPÓN | DH2: PUNTOS | DI2: ESPAÑA | DJ2: ARABIA S. | DK2: PUNTOS | DL2: BÉLGICA | DM2: IRÁN | DN2: PUNTOS | DO2: URUGUAY | DP2: CABO VERDE | DQ2: PUNTOS | DR2: NUEVA ZELAN | DS2: EGIPTO | DT2: PUNTOS | DU2: ARGENTINA | DV2: AUSTRIA | DW2: PUNTOS | DX2: FRANCIA | DY2: IRAK | DZ2: PUNTOS | EA2: NORUEGA | EB2: SENEGAL | EC2: PUNTOS | ED2: JORDANIA | EE2: ARGELIA | EF2: PUNTOS | EG2: PORTUGAL | EH2: UZBEKISTAN | EI2: PUNTOS | EJ2: INGLATERRA | EK2: GHANA | EL2: PUNTOS | EM2: PANAMA | EN2: CROACIA | EO2: PUNTOS | EP2: COLOMBIA | EQ2: RIO CONGO | ER2: PUNTOS | EU2: PUNTOS | EX2: PUNTOS | FA2: PUNTOS | FD2: PUNTOS | FG2: PUNTOS | FJ2: PUNTOS | FM2: PUNTOS | FP2: PUNTOS | FS2: PUNTOS | FV2: PUNTOS | FY2: PUNTOS | GB2: PUNTOS | GE2: PUNTOS | GH2: PUNTOS | GK2: PUNTOS | GN2: PUNTOS | GQ2: PUNTOS | GT2: PUNTOS | GW2: PUNTOS | GZ2: PUNTOS | HC2: PUNTOS | HF2: PUNTOS | HI2: PUNTOS | HL2: PUNTOS | HO2: PUNTOS | HR2: PUNTOS | HU2: PUNTOS | HX2: PUNTOS | IA2: PUNTOS | ID2: PUNTOS | IG2: PUNTOS | IJ2: PUNTOS | IM2: PUNTOS | IP2: PUNTOS | IS2: PUNTOS | IV2: PUNTOS | IY2: PUNTOS | JB2: PUNTOS | JE2: PUNTOS | JH2: PUNTOS | JK2: PUNTOS | JN2: PUNTOS | JQ2: PUNTOS | JT2: PUNTOS | JW2: PUNTOS | JZ2: PUNTOS | KC2: PUNTOS | KF2: PUNTOS | KI2: PUNTOS | KL2: PUNTOS | KO2: PUNTOS | KR2: PUNTOS | KU2: PUNTOS | KX2: PUNTOS | LA2: PUNTOS | LD2: PUNTOS | LF2: PUNTOS | LH2: PUNTOS | LJ2: PUNTOS | LL2: PUNTOS | LN2: PUNTOS
E3: 2 | F3: 0 | H3: 2 | I3: 1 | K3: 1 | L3: 1 | N3: 4 | O3: 1 | Q3: 1 | R3: 1 | T3: 1 | U3: 1 | W3: 0 | X3: 1 | Z3: 2 | AA3: 0 | AC3: 7 | AD3: 1 | AF3: 2 | AG3: 2 | AI3: 1 | AJ3: 0 | AL3: 5 | AM3: 1 | AO3: 0 | AP3: 0 | AR3: 1 | AS3: 1 | AU3: 1 | AV3: 1 | AX3: 2 | AY3: 2 | BA3: 3 | BB3: 1 | BD3: 1 | BE3: 4 | BG3: 3 | BH3: 0 | BJ3: 3 | BK3: 1 | BM3: 1 | BN3: 1 | BP3: 4 | BQ3: 2 | BS3: 1 | BT3: 0 | BV3: 1 | BW3: 3
A4: 1 | B4: Gustavo Potosí Arango | C4: =SUM(G4,J4,M4,P4,S4,V4,Y4,AB4,AE4,AH4,AK4,AN4,AQ4,AT4,AW4,AZ4,BC4,BF4,BI4,BL4,BO4,BR4,BU4,BX4,CA4,CD4,CG4,CJ4,CM4,CP4,CS4,CV4,CY4,DB4,DE4,DH4,DK4,DN4,DQ4,DT4,DW4,DZ4,EC4,EF4,EI4,EL4,EO4,ER4,EU4,EX4,FA4,FD4,FG4,FJ4,FM4,FP4,FS4,FV4,FY4,GB4,GE4,GH4,GK4,GN4,GQ4,GT4,GW4,GZ4,HC4,HF4,HI4,HL4,HO4,HR4,HU4,HX4,IA4,ID4,IG4,IJ4,IM4,IP4,IS4,IV4,IY4,JB4,JE4,JH4,JK4,JN4,JQ4,JT4,JW4,JZ4,KC4,KF4,KI4,KL4,KO4,KR4,KU4,KX4,LA4,LD4,LF4,LH4,LJ4,LL4) -> 22 | D4: =VLOOKUP(B4,polla,2,FALSE) -> 5 | E4: 2 | F4: 1 | G4: =IF(OR(ISBLANK(E4),ISBLANK(F4),ISBLANK(E$3)),"",IF(AND(E4=E$3,F$3=F4),3,IF(AND(E$3>F$3,E4>F4),1,IF(AND(E$3<F$3,E4<F4),1,IF(AND(E$3=F$3,E4=F4),1,0))))) -> 1 | H4: 0 | I4: 0 | J4: =IF(OR(ISBLANK(H4),ISBLANK(I4),ISBLANK(H$3)),"",IF(AND(H4=H$3,I$3=I4),3,IF(AND(H$3>I$3,H4>I4),1,IF(AND(H$3<I$3,H4<I4),1,IF(AND(H$3=I$3,H4=I4),1,0))))) -> 0 | K4: 1 | L4: 1 | M4: =IF(OR(ISBLANK(K4),ISBLANK(L4),ISBLANK(K$3)),"",IF(AND(K4=K$3,L$3=L4),3,IF(AND(K$3>L$3,K4>L4),1,IF(AND(K$3<L$3,K4<L4),1,IF(AND(K$3=L$3,K4=L4),1,0))))) -> 3 | N4: 1 | O4: 1 | P4: =IF(OR(ISBLANK(N4),ISBLANK(O4),ISBLANK(N$3)),"",IF(AND(N4=N$3,O$3=O4),3,IF(AND(N$3>O$3,N4>O4),1,IF(AND(N$3<O$3,N4<O4),1,IF(AND(N$3=O$3,N4=O4),1,0))))) -> 0 | Q4: 0 | R4: 3 | S4: =IF(OR(ISBLANK(Q4),ISBLANK(R4),ISBLANK(Q$3)),"",IF(AND(Q4=Q$3,R$3=R4),3,IF(AND(Q$3>R$3,Q4>R4),1,IF(AND(Q$3<R$3,Q4<R4),1,IF(AND(Q$3=R$3,Q4=R4),1,0))))) -> 0 | T4: 1 | U4: 2 | V4: =IF(OR(ISBLANK(T4),ISBLANK(U4),ISBLANK(T$3)),"",IF(AND(T4=T$3,U$3=U4),3,IF(AND(T$3>U$3,T4>U4),1,IF(AND(T$3<U$3,T4<U4),1,IF(AND(T$3=U$3,T4=U4),1,0))))) -> 0 | W4: 0 | X4: 1 | Y4: =IF(OR(ISBLANK(W4),ISBLANK(X4),ISBLANK(W$3)),"",IF(AND(W4=W$3,X$3=X4),3,IF(AND(W$3>X$3,W4>X4),1,IF(AND(W$3<X$3,W4<X4),1,IF(AND(W$3=X$3,W4=X4),1,0))))) -> 3 | Z4: 0 | AA4: 3 | AB4: =IF(OR(ISBLANK(Z4),ISBLANK(AA4),ISBLANK(Z$3)),"",IF(AND(Z4=Z$3,AA$3=AA4),3,IF(AND(Z$3>AA$3,Z4>AA4),1,IF(AND(Z$3<AA$3,Z4<AA4),1,IF(AND(Z$3=AA$3,Z4=AA4),1,0))))) -> 0 | AC4: 6 | AD4: 0 | AE4: =IF(OR(ISBLANK(AC4),ISBLANK(AD4),ISBLANK(AC$3)),"",IF(AND(AC4=AC$3,AD$3=AD4),3,IF(AND(AC$3>AD$3,AC4>AD4),1,IF(AND(AC$3<AD$3,AC4<AD4),1,IF(AND(AC$3=AD$3,AC4=AD4),1,0))))) -> 1 | AF4: 2 | AG4: 2 | AH4: =IF(OR(ISBLANK(AF4),ISBLANK(AG4),ISBLANK(AF$3)),"",IF(AND(AF4=AF$3,AG$3=AG4),3,IF(AND(AF$3>AG$3,AF4>AG4),1,IF(AND(AF$3<AG$3,AF4<AG4),1,IF(AND(AF$3=AG$3,AF4=AG4),1,0))))) -> 3 | AI4: 1 | AJ4: 2 | AK4: =IF(OR(ISBLANK(AI4),ISBLANK(AJ4),ISBLANK(AI$3)),"",IF(AND(AI4=AI$3,AJ$3=AJ4),3,IF(AND(AI$3>AJ$3,AI4>AJ4),1,IF(AND(AI$3<AJ$3,AI4<AJ4),1,IF(AND(AI$3=AJ$3,AI4=AJ4),1,0))))) -> 0 | AL4: 3 | AM4: 3 | AN4: =IF(OR(ISBLANK(AL4),ISBLANK(AM4),ISBLANK(AL$3)),"",IF(AND(AL4=AL$3,AM$3=AM4),3,IF(AND(AL$3>AM$3,AL4>AM4),1,IF(AND(AL$3<AM$3,AL4<AM4),1,IF(AND(AL$3=AM$3,AL4=AM4),1,0))))) -> 0 | AO4: 5 | AP4: 0 | AQ4: =IF(OR(ISBLANK(AO4),ISBLANK(AP4),ISBLANK(AO$3)),"",IF(AND(AO4=AO$3,AP$3=AP4),3,IF(AND(AO$3>AP$3,AO4>AP4),1,IF(AND(AO$3<AP$3,AO4<AP4),1,IF(AND(AO$3=AP$3,AO4=AP4),1,0))))) -> 0 | AR4: 3 | AS4: 1 | AT4: =IF(OR(ISBLANK(AR4),ISBLANK(AS4),ISBLANK(AR$3)),"",IF(AND(AR4=AR$3,AS$3=AS4),3,IF(AND(AR$3>AS$3,AR4>AS4),1,IF(AND(AR$3<AS$3,AR4<AS4),1,IF(AND(AR$3=AS$3,AR4=AS4),1,0))))) -> 0 | AU4: 0 | AV4: 1 | AW4: =IF(OR(ISBLANK(AU4),ISBLANK(AV4),ISBLANK(AU$3)),"",IF(AND(AU4=AU$3,AV$3=AV4),3,IF(AND(AU$3>AV$3,AU4>AV4),1,IF(AND(AU$3<AV$3,AU4<AV4),1,IF(AND(AU$3=AV$3,AU4=AV4),1,0))))) -> 0 | AX4: 1 | AY4: 0 | AZ4: =IF(OR(ISBLANK(AX4),ISBLANK(AY4),ISBLANK(AX$3)),"",IF(AND(AX4=AX$3,AY$3=AY4),3,IF(AND(AX$3>AY$3,AX4>AY4),1,IF(AND(AX$3<AY$3,AX4<AY4),1,IF(AND(AX$3=AY$3,AX4=AY4),1,0))))) -> 0 | BA4: 3 | BB4: 1 | BC4: =IF(OR(ISBLANK(BA4),ISBLANK(BB4),ISBLANK(BA$3)),"",IF(AND(BA4=BA$3,BB$3=BB4),3,IF(AND(BA$3>BB$3,BA4>BB4),1,IF(AND(BA$3<BB$3,BA4<BB4),1,IF(AND(BA$3=BB$3,BA4=BB4),1,0))))) -> 3 | BD4: 0 | BE4: 4 | BF4: =IF(OR(ISBLANK(BD4),ISBLANK(BE4),ISBLANK(BD$3)),"",IF(AND(BD4=BD$3,BE$3=BE4),3,IF(AND(BD$3>BE$3,BD4>BE4),1,IF(AND(BD$3<BE$3,BD4<BE4),1,IF(AND(BD$3=BE$3,BD4=BE4),1,0))))) -> 1 | BG4: 2 | BH4: 1 | BI4: =IF(OR(ISBLANK(BG4),ISBLANK(BH4),ISBLANK(BG$3)),"",IF(AND(BG4=BG$3,BH$3=BH4),3,IF(AND(BG$3>BH$3,BG4>BH4),1,IF(AND(BG$3<BH$3,BG4<BH4),1,IF(AND(BG$3=BH$3,BG4=BH4),1,0))))) -> 1 | BJ4: 2 | BK4: 0 | BL4: =IF(OR(ISBLANK(BJ4),ISBLANK(BK4),ISBLANK(BJ$3)),"",IF(AND(BJ4=BJ$3,BK$3=BK4),3,IF(AND(BJ$3>BK$3,BJ4>BK4),1,IF(AND(BJ$3<BK$3,BJ4<BK4),1,IF(AND(BJ$3=BK$3,BJ4=BK4),1,0))))) -> 1 | BM4: 3 | BN4: 0 | BO4: =IF(OR(ISBLANK(BM4),ISBLANK(BN4),ISBLANK(BM$3)),"",IF(AND(BM4=BM$3,BN$3=BN4),3,IF(AND(BM$3>BN$3,BM4>BN4),1,IF(AND(BM$3<BN$3,BM4<BN4),1,IF(AND(BM$3=BN$3,BM4=BN4),1,0))))) -> 0 | BP4: 2 | BQ4: 0 | BR4: =IF(OR(ISBLANK(BP4),ISBLANK(BQ4),ISBLANK(BP$3)),"",IF(AND(BP4=BP$3,BQ$3=BQ4),3,IF(AND(BP$3>BQ$3,BP4>BQ4),1,IF(AND(BP$3<BQ$3,BP4<BQ4),1,IF(AND(BP$3=BQ$3,BP4=BQ4),1,0))))) -> 1 | BS4: 1 | BT4: 0 | BU4: =IF(OR(ISBLANK(BS4),ISBLANK(BT4),ISBLANK(BS$3)),"",IF(AND(BS4=BS$3,BT$3=BT4),3,IF(AND(BS$3>BT$3,BS4>BT4),1,IF(AND(BS$3<BT$3,BS4<BT4),1,IF(AND(BS$3=BT$3,BS4=BT4),1,0))))) -> 3 | BV4: 0 | BW4: 2 | BX4: =IF(OR(ISBLANK(BV4),ISBLANK(BW4),ISBLANK(BV$3)),"",IF(AND(BV4=BV$3,BW$3=BW4),3,IF(AND(BV$3>BW$3,BV4>BW4),1,IF(AND(BV$3<BW$3,BV4<BW4),1,IF(AND(BV$3=BW$3,BV4=BW4),1,0))))) -> 1 | BY4: 0 | BZ4: 1 | CA4: =IF(OR(ISBLANK(BY4),ISBLANK(BZ4),ISBLANK(BY$3)),"",IF(AND(BY4=BY$3,BZ$3=BZ4),3,IF(AND(BY$3>BZ$3,BY4>BZ4),1,IF(AND(BY$3<BZ$3,BY4<BZ4),1,IF(AND(BY$3=BZ$3,BY4=BZ4),1,0))))) | CB4: 1 | CC4: 2 | CD4: =IF(OR(ISBLANK(CB4),ISBLANK(CC4),ISBLANK(CB$3)),"",IF(AND(CB4=CB$3,CC$3=CC4),3,IF(AND(CB$3>CC$3,CB4>CC4),1,IF(AND(CB$3<CC$3,CB4<CC4),1,IF(AND(CB$3=CC$3,CB4=CC4),1,0))))) | CE4: 2 | CF4: 1 | CG4: =IF(OR(ISBLANK(CE4),ISBLANK(CF4),ISBLANK(CE$3)),"",IF(AND(CE4=CE$3,CF$3=CF4),3,IF(AND(CE$3>CF$3,CE4>CF4),1,IF(AND(CE$3<CF$3,CE4<CF4),1,IF(AND(CE$3=CF$3,CE4=CF4),1,0))))) | CH4: 1 | CI4: 2 | CJ4: =IF(OR(ISBLANK(CH4),ISBLANK(CI4),ISBLANK(CH$3)),"",IF(AND(CH4=CH$3,CI$3=CI4),3,IF(AND(CH$3>CI$3,CH4>CI4),1,IF(AND(CH$3<CI$3,CH4<CI4),1,IF(AND(CH$3=CI$3,CH4=CI4),1,0))))) | CK4: 2 | CL4: 2 | CM4: =IF(OR(ISBLANK(CK4),ISBLANK(CL4),ISBLANK(CK$3)),"",IF(AND(CK4=CK$3,CL$3=CL4),3,IF(AND(CK$3>CL$3,CK4>CL4),1,IF(AND(CK$3<CL$3,CK4<CL4),1,IF(AND(CK$3=CL$3,CK4=CL4),1,0))))) | CN4: 1 | CO4: 3 | CP4: =IF(OR(ISBLANK(CN4),ISBLANK(CO4),ISBLANK(CN$3)),"",IF(AND(CN4=CN$3,CO$3=CO4),3,IF(AND(CN$3>CO$3,CN4>CO4),1,IF(AND(CN$3<CO$3,CN4<CO4),1,IF(AND(CN$3=CO$3,CN4=CO4),1,0))))) | CQ4: 4 | CR4: 0 | CS4: =IF(OR(ISBLANK(CQ4),ISBLANK(CR4),ISBLANK(CQ$3)),"",IF(AND(CQ4=CQ$3,CR$3=CR4),3,IF(AND(CQ$3>CR$3,CQ4>CR4),1,IF(AND(CQ$3<CR$3,CQ4<CR4),1,IF(AND(CQ$3=CR$3,CQ4=CR4),1,0))))) | CT4: 0 | CU4: 2 | CV4: =IF(OR(ISBLANK(CT4),ISBLANK(CU4),ISBLANK(CT$3)),"",IF(AND(CT4=CT$3,CU$3=CU4),3,IF(AND(CT$3>CU$3,CT4>CU4),1,IF(AND(CT$3<CU$3,CT4<CU4),1,IF(AND(CT$3=CU$3,CT4=CU4),1,0))))) | CW4: 2 | CX4: 0 | CY4: =IF(OR(ISBLANK(CW4),ISBLANK(CX4),ISBLANK(CW$3)),"",IF(AND(CW4=CW$3,CX$3=CX4),3,IF(AND(CW$3>CX$3,CW4>CX4),1,IF(AND(CW$3<CX$3,CW4<CX4),1,IF(AND(CW$3=CX$3,CW4=CX4),1,0))))) | CZ4: 3 | DA4: 1 | DB4: =IF(OR(ISBLANK(CZ4),ISBLANK(DA4),ISBLANK(CZ$3)),"",IF(AND(CZ4=CZ$3,DA$3=DA4),3,IF(AND(CZ$3>DA$3,CZ4>DA4),1,IF(AND(CZ$3<DA$3,CZ4<DA4),1,IF(AND(CZ$3=DA$3,CZ4=DA4),1,0))))) | DC4: 3 | DD4: 0 | DE4: =IF(OR(ISBLANK(DC4),ISBLANK(DD4),ISBLANK(DC$3)),"",IF(AND(DC4=DC$3,DD$3=DD4),3,IF(AND(DC$3>DD$3,DC4>DD4),1,IF(AND(DC$3<DD$3,DC4<DD4),1,IF(AND(DC$3=DD$3,DC4=DD4),1,0))))) | DF4: 2 | DG4: 3 | DH4: =IF(OR(ISBLANK(DF4),ISBLANK(DG4),ISBLANK(DF$3)),"",IF(AND(DF4=DF$3,DG$3=DG4),3,IF(AND(DF$3>DG$3,DF4>DG4),1,IF(AND(DF$3<DG$3,DF4<DG4),1,IF(AND(DF$3=DG$3,DF4=DG4),1,0))))) | DI4: 3 | DJ4: 1 | DK4: =IF(OR(ISBLANK(DI4),ISBLANK(DJ4),ISBLANK(DI$3)),"",IF(AND(DI4=DI$3,DJ$3=DJ4),3,IF(AND(DI$3>DJ$3,DI4>DJ4),1,IF(AND(DI$3<DJ$3,DI4<DJ4),1,IF(AND(DI$3=DJ$3,DI4=DJ4),1,0))))) | DL4: 1 | DM4: 0 | DN4: =IF(OR(ISBLANK(DL4),ISBLANK(DM4),ISBLANK(DL$3)),"",IF(AND(DL4=DL$3,DM$3=DM4),3,IF(AND(DL$3>DM$3,DL4>DM4),1,IF(AND(DL$3<DM$3,DL4<DM4),1,IF(AND(DL$3=DM$3,DL4=DM4),1,0))))) | DO4: 0 | DP4: 2 | DQ4: =IF(OR(ISBLANK(DO4),ISBLANK(DP4),ISBLANK(DO$3)),"",IF(AND(DO4=DO$3,DP$3=DP4),3,IF(AND(DO$3>DP$3,DO4>DP4),1,IF(AND(DO$3<DP$3,DO4<DP4),1,IF(AND(DO$3=DP$3,DO4=DP4),1,0))))) | DR4: 0 | DS4: 2 | DT4: =IF(OR(ISBLANK(DR4),ISBLANK(DS4),ISBLANK(DR$3)),"",IF(AND(DR4=DR$3,DS$3=DS4),3,IF(AND(DR$3>DS$3,DR4>DS4),1,IF(AND(DR$3<DS$3,DR4<DS4),1,IF(AND(DR$3=DS$3,DR4=DS4),1,0))))) | DU4: 2 | DV4: 0 | DW4: =IF(OR(ISBLANK(DU4),ISBLANK(DV4),ISBLANK(DU$3)),"",IF(AND(DU4=DU$3,DV$3=DV4),3,IF(AND(DU$3>DV$3,DU4>DV4),1,IF(AND(DU$3<DV$3,DU4<DV4),1,IF(AND(DU$3=DV$3,DU4=DV4),1,0))))) | DX4: 6 | DY4: 0 | DZ4: =IF(OR(ISBLANK(DX4),ISBLANK(DY4),ISBLANK(DX$3)),"",IF(AND(DX4=DX$3,DY$3=DY4),3,IF(AND(DX$3>DY$3,DX4>DY4),1,IF(AND(DX$3<DY$3,DX4<DY4),1,IF(AND(DX$3=DY$3,DX4=DY4),1,0))))) | EA4: 2 | EB4: 1 | EC4: =IF(OR(ISBLANK(EA4),ISBLANK(EB4),ISBLANK(EA$3)),"",IF(AND(EA4=EA$3,EB$3=EB4),3,IF(AND(EA$3>EB$3,EA4>EB4),1,IF(AND(EA$3<EB$3,EA4<EB4),1,IF(AND(EA$3=EB$3,EA4=EB4),1,0))))) | ED4: 0 | EE4: 2 | EF4: =IF(OR(ISBLANK(ED4),ISBLANK(EE4),ISBLANK(ED$3)),"",IF(AND(ED4=ED$3,EE$3=EE4),3,IF(AND(ED$3>EE$3,ED4>EE4),1,IF(AND(ED$3<EE$3,ED4<EE4),1,IF(AND(ED$3=EE$3,ED4=EE4),1,0))))) | EG4: 2 | EH4: 0 | EI4: =IF(OR(ISBLANK(EG4),ISBLANK(EH4),ISBLANK(EG$3)),"",IF(AND(EG4=EG$3,EH$3=EH4),3,IF(AND(EG$3>EH$3,EG4>EH4),1,IF(AND(EG$3<EH$3,EG4<EH4),1,IF(AND(EG$3=EH$3,EG4=EH4),1,0))))) | EJ4: 1 | EK4: 0 | EL4: =IF(OR(ISBLANK(EJ4),ISBLANK(EK4),ISBLANK(EJ$3)),"",IF(AND(EJ4=EJ$3,EK$3=EK4),3,IF(AND(EJ$3>EK$3,EJ4>EK4),1,IF(AND(EJ$3<EK$3,EJ4<EK4),1,IF(AND(EJ$3=EK$3,EJ4=EK4),1,0))))) | EM4: 1 | EN4: 3 | EO4: =IF(OR(ISBLANK(EM4),ISBLANK(EN4),ISBLANK(EM$3)),"",IF(AND(EM4=EM$3,EN$3=EN4),3,IF(AND(EM$3>EN$3,EM4>EN4),1,IF(AND(EM$3<EN$3,EM4<EN4),1,IF(AND(EM$3=EN$3,EM4=EN4),1,0))))) | EP4: 2 | EQ4: 1 | ER4: =IF(OR(ISBLANK(EP4),ISBLANK(EQ4),ISBLANK(EP$3)),"",IF(AND(EP4=EP$3,EQ$3=EQ4),3,IF(AND(EP$3>EQ$3,EP4>EQ4),1,IF(AND(EP$3<EQ$3,EP4<EQ4),1,IF(AND(EP$3=EQ$3,EP4=EQ4),1,0))))) | EU4: =IF(OR(ISBLANK(ES4),ISBLANK(ET4),ISBLANK(ES$3)),"",IF(AND(ES4=ES$3,ET$3=ET4),3,IF(AND(ES$3>ET$3,ES4>ET4),1,IF(AND(ES$3<ET$3,ES4<ET4),1,IF(AND(ES$3=ET$3,ES4=ET4),1,0))))) | EX4: =IF(OR(ISBLANK(EV4),ISBLANK(EW4),ISBLANK(EV$3)),"",IF(AND(EV4=EV$3,EW$3=EW4),3,IF(AND(EV$3>EW$3,EV4>EW4),1,IF(AND(EV$3<EW$3,EV4<EW4),1,IF(AND(EV$3=EW$3,EV4=EW4),1,0))))) | FA4: =IF(OR(ISBLANK(EY4),ISBLANK(EZ4),ISBLANK(EY$3)),"",IF(AND(EY4=EY$3,EZ$3=EZ4),3,IF(AND(EY$3>EZ$3,EY4>EZ4),1,IF(AND(EY$3<EZ$3,EY4<EZ4),1,IF(AND(EY$3=EZ$3,EY4=EZ4),1,0))))) | FD4: =IF(OR(ISBLANK(FB4),ISBLANK(FC4),ISBLANK(FB$3)),"",IF(AND(FB4=FB$3,FC$3=FC4),3,IF(AND(FB$3>FC$3,FB4>FC4),1,IF(AND(FB$3<FC$3,FB4<FC4),1,IF(AND(FB$3=FC$3,FB4=FC4),1,0))))) | FG4: =IF(OR(ISBLANK(FE4),ISBLANK(FF4),ISBLANK(FE$3)),"",IF(AND(FE4=FE$3,FF$3=FF4),3,IF(AND(FE$3>FF$3,FE4>FF4),1,IF(AND(FE$3<FF$3,FE4<FF4),1,IF(AND(FE$3=FF$3,FE4=FF4),1,0))))) | FJ4: =IF(OR(ISBLANK(FH4),ISBLANK(FI4),ISBLANK(FH$3)),"",IF(AND(FH4=FH$3,FI$3=FI4),3,IF(AND(FH$3>FI$3,FH4>FI4),1,IF(AND(FH$3<FI$3,FH4<FI4),1,IF(AND(FH$3=FI$3,FH4=FI4),1,0))))) | FM4: =IF(OR(ISBLANK(FK4),ISBLANK(FL4),ISBLANK(FK$3)),"",IF(AND(FK4=FK$3,FL$3=FL4),3,IF(AND(FK$3>FL$3,FK4>FL4),1,IF(AND(FK$3<FL$3,FK4<FL4),1,IF(AND(FK$3=FL$3,FK4=FL4),1,0))))) | FP4: =IF(OR(ISBLANK(FN4),ISBLANK(FO4),ISBLANK(FN$3)),"",IF(AND(FN4=FN$3,FO$3=FO4),3,IF(AND(FN$3>FO$3,FN4>FO4),1,IF(AND(FN$3<FO$3,FN4<FO4),1,IF(AND(FN$3=FO$3,FN4=FO4),1,0))))) | FS4: =IF(OR(ISBLANK(FQ4),ISBLANK(FR4),ISBLANK(FQ$3)),"",IF(AND(FQ4=FQ$3,FR$3=FR4),3,IF(AND(FQ$3>FR$3,FQ4>FR4),1,IF(AND(FQ$3<FR$3,FQ4<FR4),1,IF(AND(FQ$3=FR$3,FQ4=FR4),1,0))))) | FV4: =IF(OR(ISBLANK(FT4),ISBLANK(FU4),ISBLANK(FT$3)),"",IF(AND(FT4=FT$3,FU$3=FU4),3,IF(AND(FT$3>FU$3,FT4>FU4),1,IF(AND(FT$3<FU$3,FT4<FU4),1,IF(AND(FT$3=FU$3,FT4=FU4),1,0))))) | FY4: =IF(OR(ISBLANK(FW4),ISBLANK(FX4),ISBLANK(FW$3)),"",IF(AND(FW4=FW$3,FX$3=FX4),3,IF(AND(FW$3>FX$3,FW4>FX4),1,IF(AND(FW$3<FX$3,FW4<FX4),1,IF(AND(FW$3=FX$3,FW4=FX4),1,0))))) | GB4: =IF(OR(ISBLANK(FZ4),ISBLANK(GA4),ISBLANK(FZ$3)),"",IF(AND(FZ4=FZ$3,GA$3=GA4),3,IF(AND(FZ$3>GA$3,FZ4>GA4),1,IF(AND(FZ$3<GA$3,FZ4<GA4),1,IF(AND(FZ$3=GA$3,FZ4=GA4),1,0))))) | GE4: =IF(OR(ISBLANK(GC4),ISBLANK(GD4),ISBLANK(GC$3)),"",IF(AND(GC4=GC$3,GD$3=GD4),3,IF(AND(GC$3>GD$3,GC4>GD4),1,IF(AND(GC$3<GD$3,GC4<GD4),1,IF(AND(GC$3=GD$3,GC4=GD4),1,0))))) | GH4: =IF(OR(ISBLANK(GF4),ISBLANK(GG4),ISBLANK(GF$3)),"",IF(AND(GF4=GF$3,GG$3=GG4),3,IF(AND(GF$3>GG$3,GF4>GG4),1,IF(AND(GF$3<GG$3,GF4<GG4),1,IF(AND(GF$3=GG$3,GF4=GG4),1,0))))) | GK4: =IF(OR(ISBLANK(GI4),ISBLANK(GJ4),ISBLANK(GI$3)),"",IF(AND(GI4=GI$3,GJ$3=GJ4),3,IF(AND(GI$3>GJ$3,GI4>GJ4),1,IF(AND(GI$3<GJ$3,GI4<GJ4),1,IF(AND(GI$3=GJ$3,GI4=GJ4),1,0))))) | GN4: =IF(OR(ISBLANK(GL4),ISBLANK(GM4),ISBLANK(GL$3)),"",IF(AND(GL4=GL$3,GM$3=GM4),3,IF(AND(GL$3>GM$3,GL4>GM4),1,IF(AND(GL$3<GM$3,GL4<GM4),1,IF(AND(GL$3=GM$3,GL4=GM4),1,0))))) | GQ4: =IF(OR(ISBLANK(GO4),ISBLANK(GP4),ISBLANK(GO$3)),"",IF(AND(GO4=GO$3,GP$3=GP4),3,IF(AND(GO$3>GP$3,GO4>GP4),1,IF(AND(GO$3<GP$3,GO4<GP4),1,IF(AND(GO$3=GP$3,GO4=GP4),1,0))))) | GT4: =IF(OR(ISBLANK(GR4),ISBLANK(GS4),ISBLANK(GR$3)),"",IF(AND(GR4=GR$3,GS$3=GS4),3,IF(AND(GR$3>GS$3,GR4>GS4),1,IF(AND(GR$3<GS$3,GR4<GS4),1,IF(AND(GR$3=GS$3,GR4=GS4),1,0))))) | GW4: =IF(OR(ISBLANK(GU4),ISBLANK(GV4),ISBLANK(GU$3)),"",IF(AND(GU4=GU$3,GV$3=GV4),3,IF(AND(GU$3>GV$3,GU4>GV4),1,IF(AND(GU$3<GV$3,GU4<GV4),1,IF(AND(GU$3=GV$3,GU4=GV4),1,0))))) | GZ4: =IF(OR(ISBLANK(GX4),ISBLANK(GY4),ISBLANK(GX$3)),"",IF(AND(GX4=GX$3,GY$3=GY4),3,IF(AND(GX$3>GY$3,GX4>GY4),1,IF(AND(GX$3<GY$3,GX4<GY4),1,IF(AND(GX$3=GY$3,GX4=GY4),1,0))))) | HC4: =IF(OR(ISBLANK(HA4),ISBLANK(HB4),ISBLANK(HA$3)),"",IF(AND(HA4=HA$3,HB$3=HB4),3,IF(AND(HA$3>HB$3,HA4>HB4),1,IF(AND(HA$3<HB$3,HA4<HB4),1,IF(AND(HA$3=HB$3,HA4=HB4),1,0))))) | HF4: =IF(OR(ISBLANK(HD4),ISBLANK(HE4),ISBLANK(HD$3)),"",IF(AND(HD4=HD$3,HE$3=HE4),3,IF(AND(HD$3>HE$3,HD4>HE4),1,IF(AND(HD$3<HE$3,HD4<HE4),1,IF(AND(HD$3=HE$3,HD4=HE4),1,0))))) | HI4: =IF(OR(ISBLANK(HG4),ISBLANK(HH4),ISBLANK(HG$3)),"",IF(AND(HG4=HG$3,HH$3=HH4),3,IF(AND(HG$3>HH$3,HG4>HH4),1,IF(AND(HG$3<HH$3,HG4<HH4),1,IF(AND(HG$3=HH$3,HG4=HH4),1,0))))) | HL4: =IF(OR(ISBLANK(HJ4),ISBLANK(HK4),ISBLANK(HJ$3)),"",IF(AND(HJ4=HJ$3,HK$3=HK4),3,IF(AND(HJ$3>HK$3,HJ4>HK4),1,IF(AND(HJ$3<HK$3,HJ4<HK4),1,IF(AND(HJ$3=HK$3,HJ4=HK4),1,0))))) | HO4: =IF(OR(ISBLANK(HM4),ISBLANK(HN4),ISBLANK(HM$3)),"",IF(AND(HM4=HM$3,HN$3=HN4),3,IF(AND(HM$3>HN$3,HM4>HN4),1,IF(AND(HM$3<HN$3,HM4<HN4),1,IF(AND(HM$3=HN$3,HM4=HN4),1,0))))) | HR4: =IF(OR(ISBLANK(HP4),ISBLANK(HQ4),ISBLANK(HP$3)),"",IF(AND(HP4=HP$3,HQ$3=HQ4),3,IF(AND(HP$3>HQ$3,HP4>HQ4),1,IF(AND(HP$3<HQ$3,HP4<HQ4),1,IF(AND(HP$3=HQ$3,HP4=HQ4),1,0))))) | HU4: =IF(OR(ISBLANK(HS4),ISBLANK(HT4),ISBLANK(HS$3)),"",IF(AND(HS4=HS$3,HT$3=HT4),3,IF(AND(HS$3>HT$3,HS4>HT4),1,IF(AND(HS$3<HT$3,HS4<HT4),1,IF(AND(HS$3=HT$3,HS4=HT4),1,0))))) | HX4: =IF(OR(ISBLANK(HV4),ISBLANK(HW4),ISBLANK(HV$3)),"",IF(AND(HV4=HV$3,HW$3=HW4),3,IF(AND(HV$3>HW$3,HV4>HW4),1,IF(AND(HV$3<HW$3,HV4<HW4),1,IF(AND(HV$3=HW$3,HV4=HW4),1,0))))) | IA4: =IF(OR(ISBLANK(HY4),ISBLANK(HZ4),ISBLANK(HY$3)),"",IF(AND(HY4=HY$3,HZ$3=HZ4),3,IF(AND(HY$3>HZ$3,HY4>HZ4),1,IF(AND(HY$3<HZ$3,HY4<HZ4),1,IF(AND(HY$3=HZ$3,HY4=HZ4),1,0))))) | ID4: =IF(OR(ISBLANK(IB4),ISBLANK(IC4),ISBLANK(IB$3)),"",IF(AND(IB4=IB$3,IC$3=IC4),3,IF(AND(IB$3>IC$3,IB4>IC4),1,IF(AND(IB$3<IC$3,IB4<IC4),1,IF(AND(IB$3=IC$3,IB4=IC4),1,0))))) | IG4: =IF(OR(ISBLANK(IE4),ISBLANK(IF4),ISBLANK(IE$3)),"",IF(AND(IE4=IE$3,IF$3=IF4),3,IF(AND(IE$3>IF$3,IE4>IF4),1,IF(AND(IE$3<IF$3,IE4<IF4),1,IF(AND(IE$3=IF$3,IE4=IF4),1,0))))) | IJ4: =IF(OR(ISBLANK(IH4),ISBLANK(II4),ISBLANK(IH$3)),"",IF(AND(IH4=IH$3,II$3=II4),3,IF(AND(IH$3>II$3,IH4>II4),1,IF(AND(IH$3<II$3,IH4<II4),1,IF(AND(IH$3=II$3,IH4=II4),1,0))))) | IM4: =IF(OR(ISBLANK(IK4),ISBLANK(IL4),ISBLANK(IK$3)),"",IF(AND(IK4=IK$3,IL$3=IL4),3,IF(AND(IK$3>IL$3,IK4>IL4),1,IF(AND(IK$3<IL$3,IK4<IL4),1,IF(AND(IK$3=IL$3,IK4=IL4),1,0))))) | IP4: =IF(OR(ISBLANK(IN4),ISBLANK(IO4),ISBLANK(IN$3)),"",IF(AND(IN4=IN$3,IO$3=IO4),3,IF(AND(IN$3>IO$3,IN4>IO4),1,IF(AND(IN$3<IO$3,IN4<IO4),1,IF(AND(IN$3=IO$3,IN4=IO4),1,0))))) | IS4: =IF(OR(ISBLANK(IQ4),ISBLANK(IR4),ISBLANK(IQ$3)),"",IF(AND(IQ4=IQ$3,IR$3=IR4),3,IF(AND(IQ$3>IR$3,IQ4>IR4),1,IF(AND(IQ$3<IR$3,IQ4<IR4),1,IF(AND(IQ$3=IR$3,IQ4=IR4),1,0))))) | IV4: =IF(OR(ISBLANK(IT4),ISBLANK(IU4),ISBLANK(IT$3)),"",IF(AND(IT4=IT$3,IU$3=IU4),3,IF(AND(IT$3>IU$3,IT4>IU4),1,IF(AND(IT$3<IU$3,IT4<IU4),1,IF(AND(IT$3=IU$3,IT4=IU4),1,0))))) | IY4: =IF(OR(ISBLANK(IW4),ISBLANK(IX4),ISBLANK(IW$3)),"",IF(AND(IW4=IW$3,IX$3=IX4),3,IF(AND(IW$3>IX$3,IW4>IX4),1,IF(AND(IW$3<IX$3,IW4<IX4),1,IF(AND(IW$3=IX$3,IW4=IX4),1,0))))) | JB4: =IF(OR(ISBLANK(IZ4),ISBLANK(JA4),ISBLANK(IZ$3)),"",IF(AND(IZ4=IZ$3,JA$3=JA4),3,IF(AND(IZ$3>JA$3,IZ4>JA4),1,IF(AND(IZ$3<JA$3,IZ4<JA4),1,IF(AND(IZ$3=JA$3,IZ4=JA4),1,0))))) | JE4: =IF(OR(ISBLANK(JC4),ISBLANK(JD4),ISBLANK(JC$3)),"",IF(AND(JC4=JC$3,JD$3=JD4),3,IF(AND(JC$3>JD$3,JC4>JD4),1,IF(AND(JC$3<JD$3,JC4<JD4),1,IF(AND(JC$3=JD$3,JC4=JD4),1,0))))) | JH4: =IF(OR(ISBLANK(JF4),ISBLANK(JG4),ISBLANK(JF$3)),"",IF(AND(JF4=JF$3,JG$3=JG4),3,IF(AND(JF$3>JG$3,JF4>JG4),1,IF(AND(JF$3<JG$3,JF4<JG4),1,IF(AND(JF$3=JG$3,JF4=JG4),1,0))))) | JK4: =IF(OR(ISBLANK(JI4),ISBLANK(JJ4),ISBLANK(JI$3)),"",IF(AND(JI4=JI$3,JJ$3=JJ4),3,IF(AND(JI$3>JJ$3,JI4>JJ4),1,IF(AND(JI$3<JJ$3,JI4<JJ4),1,IF(AND(JI$3=JJ$3,JI4=JJ4),1,0))))) | JN4: =IF(OR(ISBLANK(JL4),ISBLANK(JM4),ISBLANK(JL$3)),"",IF(AND(JL4=JL$3,JM$3=JM4),3,IF(AND(JL$3>JM$3,JL4>JM4),1,IF(AND(JL$3<JM$3,JL4<JM4),1,IF(AND(JL$3=JM$3,JL4=JM4),1,0))))) | JQ4: =IF(OR(ISBLANK(JO4),ISBLANK(JP4),ISBLANK(JO$3)),"",IF(AND(JO4=JO$3,JP$3=JP4),3,IF(AND(JO$3>JP$3,JO4>JP4),1,IF(AND(JO$3<JP$3,JO4<JP4),1,IF(AND(JO$3=JP$3,JO4=JP4),1,0))))) | JT4: =IF(OR(ISBLANK(JR4),ISBLANK(JS4),ISBLANK(JR$3)),"",IF(AND(JR4=JR$3,JS$3=JS4),3,IF(AND(JR$3>JS$3,JR4>JS4),1,IF(AND(JR$3<JS$3,JR4<JS4),1,IF(AND(JR$3=JS$3,JR4=JS4),1,0))))) | JW4: =IF(OR(ISBLANK(JU4),ISBLANK(JV4),ISBLANK(JU$3)),"",IF(AND(JU4=JU$3,JV$3=JV4),3,IF(AND(JU$3>JV$3,JU4>JV4),1,IF(AND(JU$3<JV$3,JU4<JV4),1,IF(AND(JU$3=JV$3,JU4=JV4),1,0))))) | JZ4: =IF(OR(ISBLANK(JX4),ISBLANK(JY4),ISBLANK(JX$3)),"",IF(AND(JX4=JX$3,JY$3=JY4),3,IF(AND(JX$3>JY$3,JX4>JY4),1,IF(AND(JX$3<JY$3,JX4<JY4),1,IF(AND(JX$3=JY$3,JX4=JY4),1,0))))) | KC4: =IF(OR(ISBLANK(KA4),ISBLANK(KB4),ISBLANK(KA$3)),"",IF(AND(KA4=KA$3,KB$3=KB4),3,IF(AND(KA$3>KB$3,KA4>KB4),1,IF(AND(KA$3<KB$3,KA4<KB4),1,IF(AND(KA$3=KB$3,KA4=KB4),1,0))))) | KF4: =IF(OR(ISBLANK(KD4),ISBLANK(KE4),ISBLANK(KD$3)),"",IF(AND(KD4=KD$3,KE$3=KE4),3,IF(AND(KD$3>KE$3,KD4>KE4),1,IF(AND(KD$3<KE$3,KD4<KE4),1,IF(AND(KD$3=KE$3,KD4=KE4),1,0))))) | KI4: =IF(OR(ISBLANK(KG4),ISBLANK(KH4),ISBLANK(KG$3)),"",IF(AND(KG4=KG$3,KH$3=KH4),5,IF(AND(KG$3>KH$3,KG4>KH4),1,IF(AND(KG$3<KH$3,KG4<KH4),1,IF(AND(KG$3=KH$3,KG4=KH4),1,0))))) | KL4: =IF(OR(ISBLANK(KJ4),ISBLANK(KK4),ISBLANK(KJ$3)),"",IF(AND(KJ4=KJ$3,KK$3=KK4),5,IF(AND(KJ$3>KK$3,KJ4>KK4),1,IF(AND(KJ$3<KK$3,KJ4<KK4),1,IF(AND(KJ$3=KK$3,KJ4=KK4),1,0))))) | KO4: =IF(OR(ISBLANK(KM4),ISBLANK(KN4),ISBLANK(KM$3)),"",IF(AND(KM4=KM$3,KN$3=KN4),5,IF(AND(KM$3>KN$3,KM4>KN4),1,IF(AND(KM$3<KN$3,KM4<KN4),1,IF(AND(KM$3=KN$3,KM4=KN4),1,0))))) | KR4: =IF(OR(ISBLANK(KP4),ISBLANK(KQ4),ISBLANK(KP$3)),"",IF(AND(KP4=KP$3,KQ$3=KQ4),5,IF(AND(KP$3>KQ$3,KP4>KQ4),1,IF(AND(KP$3<KQ$3,KP4<KQ4),1,IF(AND(KP$3=KQ$3,KP4=KQ4),1,0))))) | KU4: =IF(OR(ISBLANK(KS4),ISBLANK(KT4),ISBLANK(KS$3)),"",IF(AND(KS4=KS$3,KT$3=KT4),5,IF(AND(KS$3>KT$3,KS4>KT4),1,IF(AND(KS$3<KT$3,KS4<KT4),1,IF(AND(KS$3=KT$3,KS4=KT4),1,0))))) | KX4: =IF(OR(ISBLANK(KV4),ISBLANK(KW4),ISBLANK(KV$3)),"",IF(AND(KV4=KV$3,KW$3=KW4),5,IF(AND(KV$3>KW$3,KV4>KW4),1,IF(AND(KV$3<KW$3,KV4<KW4),1,IF(AND(KV$3=KW$3,KV4=KW4),1,0))))) | LA4: =IF(OR(ISBLANK(KY4),ISBLANK(KZ4),ISBLANK(KY$3)),"",IF(AND(KY4=KY$3,KZ$3=KZ4),5,IF(AND(KY$3>KZ$3,KY4>KZ4),1,IF(AND(KY$3<KZ$3,KY4<KZ4),1,IF(AND(KY$3=KZ$3,KY4=KZ4),1,0))))) | LD4: =IF(OR(ISBLANK(LB4),ISBLANK(LC4),ISBLANK(LB$3)),"",IF(AND(LB4=LB$3,LC$3=LC4),5,IF(AND(LB$3>LC$3,LB4>LC4),1,IF(AND(LB$3<LC$3,LB4<LC4),1,IF(AND(LB$3=LC$3,LB4=LC4),1,0))))) | LF4: =IF(ISBLANK(LE4),"",IF(LE2=LE4,5,0)) | LH4: =IF(ISBLANK(LG4),"",IF(LG2=LG4,5,0)) | LJ4: =IF(ISBLANK(LI4),"",IF(LI2=LI4,5,0)) | LL4: =IF(ISBLANK(LK4),"",IF(LK2=LK4,5,0)) | LN4: =IF(ISBLANK(LM4),"",IF(LM2=LM4,5,0))
A5: 2 | B5: JUAN CARLOS GIRALDO GOMEZ | C5: =SUM(G5,J5,M5,P5,S5,V5,Y5,AB5,AE5,AH5,AK5,AN5,AQ5,AT5,AW5,AZ5,BC5,BF5,BI5,BL5,BO5,BR5,BU5,BX5,CA5,CD5,CG5,CJ5,CM5,CP5,CS5,CV5,CY5,DB5,DE5,DH5,DK5,DN5,DQ5,DT5,DW5,DZ5,EC5,EF5,EI5,EL5,EO5,ER5,EU5,EX5,FA5,FD5,FG5,FJ5,FM5,FP5,FS5,FV5,FY5,GB5,GE5,GH5,GK5,GN5,GQ5,GT5,GW5,GZ5,HC5,HF5,HI5,HL5,HO5,HR5,HU5,HX5,IA5,ID5,IG5,IJ5,IM5,IP5,IS5,IV5,IY5,JB5,JE5,JH5,JK5,JN5,JQ5,JT5,JW5,JZ5,KC5,KF5,KI5,KL5,KO5,KR5,KU5,KX5,LA5,LD5,LF5,LH5,LJ5,LL5) -> 20 | D5: =VLOOKUP(B5,polla,2,FALSE) -> 4 | E5: 2 | F5: 1 | G5: =IF(OR(ISBLANK(E5),ISBLANK(F5),ISBLANK(E$3)),"",IF(AND(E5=E$3,F$3=F5),3,IF(AND(E$3>F$3,E5>F5),1,IF(AND(E$3<F$3,E5<F5),1,IF(AND(E$3=F$3,E5=F5),1,0))))) -> 1 | H5: 2 | I5: 1 | J5: =IF(OR(ISBLANK(H5),ISBLANK(I5),ISBLANK(H$3)),"",IF(AND(H5=H$3,I$3=I5),3,IF(AND(H$3>I$3,H5>I5),1,IF(AND(H$3<I$3,H5<I5),1,IF(AND(H$3=I$3,H5=I5),1,0))))) -> 3 | K5: 2 | L5: 1 | M5: =IF(OR(ISBLANK(K5),ISBLANK(L5),ISBLANK(K$3)),"",IF(AND(K5=K$3,L$3=L5),3,IF(AND(K$3>L$3,K5>L5),1,IF(AND(K$3<L$3,K5<L5),1,IF(AND(K$3=L$3,K5=L5),1,0))))) -> 0 | N5: 2 | O5: 2 | P5: =IF(OR(ISBLANK(N5),ISBLANK(O5),ISBLANK(N$3)),"",IF(AND(N5=N$3,O$3=O5),3,IF(AND(N$3>O$3,N5>O5),1,IF(AND(N$3<O$3,N5<O5),1,IF(AND(N$3=O$3,N5=O5),1,0))))) -> 0 | Q5: 0 | R5: 2 | S5: =IF(OR(ISBLANK(Q5),ISBLANK(R5),ISBLANK(Q$3)),"",IF(AND(Q5=Q$3,R$3=R5),3,IF(AND(Q$3>R$3,Q5>R5),1,IF(AND(Q$3<R$3,Q5<R5),1,IF(AND(Q$3=R$3,Q5=R5),1,0))))) -> 0 | T5: 2 | U5: 1 | V5: =IF(OR(ISBLANK(T5),ISBLANK(U5),ISBLANK(T$3)),"",IF(AND(T5=T$3,U$3=U5),3,IF(AND(T$3>U$3,T5>U5),1,IF(AND(T$3<U$3,T5<U5),1,IF(AND(T$3=U$3,T5=U5),1,0))))) -> 0 | W5: 0 | X5: 1 | Y5: =IF(OR(ISBLANK(W5),ISBLANK(X5),ISBLANK(W$3)),"",IF(AND(W5=W$3,X$3=X5),3,IF(AND(W$3>X$3,W5>X5),1,IF(AND(W$3<X$3,W5<X5),1,IF(AND(W$3=X$3,W5=X5),1,0))))) -> 3 | Z5: 0 | AA5: 0 | AB5: =IF(OR(ISBLANK(Z5),ISBLANK(AA5),ISBLANK(Z$3)),"",IF(AND(Z5=Z$3,AA$3=AA5),3,IF(AND(Z$3>AA$3,Z5>AA5),1,IF(AND(Z$3<AA$3,Z5<AA5),1,IF(AND(Z$3=AA$3,Z5=AA5),1,0))))) -> 0 | AC5: 4 | AD5: 0 | AE5: =IF(OR(ISBLANK(AC5),ISBLANK(AD5),ISBLANK(AC$3)),"",IF(AND(AC5=AC$3,AD$3=AD5),3,IF(AND(AC$3>AD$3,AC5>AD5),1,IF(AND(AC$3<AD$3,AC5<AD5),1,IF(AND(AC$3=AD$3,AC5=AD5),1,0))))) -> 1 | AF5: 2 | AG5: 0 | AH5: =IF(OR(ISBLANK(AF5),ISBLANK(AG5),ISBLANK(AF$3)),"",IF(AND(AF5=AF$3,AG$3=AG5),3,IF(AND(AF$3>AG$3,AF5>AG5),1,IF(AND(AF$3<AG$3,AF5<AG5),1,IF(AND(AF$3=AG$3,AF5=AG5),1,0))))) -> 0 | AI5: 1 | AJ5: 1 | AK5: =IF(OR(ISBLANK(AI5),ISBLANK(AJ5),ISBLANK(AI$3)),"",IF(AND(AI5=AI$3,AJ$3=AJ5),3,IF(AND(AI$3>AJ$3,AI5>AJ5),1,IF(AND(AI$3<AJ$3,AI5<AJ5),1,IF(AND(AI$3=AJ$3,AI5=AJ5),1,0))))) -> 0 | AL5: 1 | AM5: 0 | AN5: =IF(OR(ISBLANK(AL5),ISBLANK(AM5),ISBLANK(AL$3)),"",IF(AND(AL5=AL$3,AM$3=AM5),3,IF(AND(AL$3>AM$3,AL5>AM5),1,IF(AND(AL$3<AM$3,AL5<AM5),1,IF(AND(AL$3=AM$3,AL5=AM5),1,0))))) -> 1 | AO5: 3 | AP5: 0 | AQ5: =IF(OR(ISBLANK(AO5),ISBLANK(AP5),ISBLANK(AO$3)),"",IF(AND(AO5=AO$3,AP$3=AP5),3,IF(AND(AO$3>AP$3,AO5>AP5),1,IF(AND(AO$3<AP$3,AO5<AP5),1,IF(AND(AO$3=AP$3,AO5=AP5),1,0))))) -> 0 | AR5: 1 | AS5: 0 | AT5: =IF(OR(ISBLANK(AR5),ISBLANK(AS5),ISBLANK(AR$3)),"",IF(AND(AR5=AR$3,AS$3=AS5),3,IF(AND(AR$3>AS$3,AR5>AS5),1,IF(AND(AR$3<AS$3,AR5<AS5),1,IF(AND(AR$3=AS$3,AR5=AS5),1,0))))) -> 0 | AU5: 0 | AV5: 1 | AW5: =IF(OR(ISBLANK(AU5),ISBLANK(AV5),ISBLANK(AU$3)),"",IF(AND(AU5=AU$3,AV$3=AV5),3,IF(AND(AU$3>AV$3,AU5>AV5),1,IF(AND(AU$3<AV$3,AU5<AV5),1,IF(AND(AU$3=AV$3,AU5=AV5),1,0))))) -> 0 | AX5: 2 | AY5: 0 | AZ5: =IF(OR(ISBLANK(AX5),ISBLANK(AY5),ISBLANK(AX$3)),"",IF(AND(AX5=AX$3,AY$3=AY5),3,IF(AND(AX$3>AY$3,AX5>AY5),1,IF(AND(AX$3<AY$3,AX5<AY5),1,IF(AND(AX$3=AY$3,AX5=AY5),1,0))))) -> 0 | BA5: 3 | BB5: 1 | BC5: =IF(OR(ISBLANK(BA5),ISBLANK(BB5),ISBLANK(BA$3)),"",IF(AND(BA5=BA$3,BB$3=BB5),3,IF(AND(BA$3>BB$3,BA5>BB5),1,IF(AND(BA$3<BB$3,BA5<BB5),1,IF(AND(BA$3=BB$3,BA5=BB5),1,0))))) -> 3 | BD5: 0 | BE5: 3 | BF5: =IF(OR(ISBLANK(BD5),ISBLANK(BE5),ISBLANK(BD$3)),"",IF(AND(BD5=BD$3,BE$3=BE5),3,IF(AND(BD$3>BE$3,BD5>BE5),1,IF(AND(BD$3<BE$3,BD5<BE5),1,IF(AND(BD$3=BE$3,BD5=BE5),1,0))))) -> 1 | BG5: 2 | BH5: 0 | BI5: =IF(OR(ISBLANK(BG5),ISBLANK(BH5),ISBLANK(BG$3)),"",IF(AND(BG5=BG$3,BH$3=BH5),3,IF(AND(BG$3>BH$3,BG5>BH5),1,IF(AND(BG$3<BH$3,BG5<BH5),1,IF(AND(BG$3=BH$3,BG5=BH5),1,0))))) -> 1 | BJ5: 2 | BK5: 0 | BL5: =IF(OR(ISBLANK(BJ5),ISBLANK(BK5),ISBLANK(BJ$3)),"",IF(AND(BJ5=BJ$3,BK$3=BK5),3,IF(AND(BJ$3>BK$3,BJ5>BK5),1,IF(AND(BJ$3<BK$3,BJ5<BK5),1,IF(AND(BJ$3=BK$3,BJ5=BK5),1,0))))) -> 1 | BM5: 2 | BN5: 1 | BO5: =IF(OR(ISBLANK(BM5),ISBLANK(BN5),ISBLANK(BM$3)),"",IF(AND(BM5=BM$3,BN$3=BN5),3,IF(AND(BM$3>BN$3,BM5>BN5),1,IF(AND(BM$3<BN$3,BM5<BN5),1,IF(AND(BM$3=BN$3,BM5=BN5),1,0))))) -> 0 | BP5: 1 | BQ5: 0 | BR5: =IF(OR(ISBLANK(BP5),ISBLANK(BQ5),ISBLANK(BP$3)),"",IF(AND(BP5=BP$3,BQ$3=BQ5),3,IF(AND(BP$3>BQ$3,BP5>BQ5),1,IF(AND(BP$3<BQ$3,BP5<BQ5),1,IF(AND(BP$3=BQ$3,BP5=BQ5),1,0))))) -> 1 | BS5: 1 | BT5: 0 | BU5: =IF(OR(ISBLANK(BS5),ISBLANK(BT5),ISBLANK(BS$3)),"",IF(AND(BS5=BS$3,BT$3=BT5),3,IF(AND(BS$3>BT$3,BS5>BT5),1,IF(AND(BS$3<BT$3,BS5<BT5),1,IF(AND(BS$3=BT$3,BS5=BT5),1,0))))) -> 3 | BV5: 0 | BW5: 2 | BX5: =IF(OR(ISBLANK(BV5),ISBLANK(BW5),ISBLANK(BV$3)),"",IF(AND(BV5=BV$3,BW$3=BW5),3,IF(AND(BV$3>BW$3,BV5>BW5),1,IF(AND(BV$3<BW$3,BV5<BW5),1,IF(AND(BV$3=BW$3,BV5=BW5),1,0))))) -> 1 | BY5: 1 | BZ5: 2 | CA5: =IF(OR(ISBLANK(BY5),ISBLANK(BZ5),ISBLANK(BY$3)),"",IF(AND(BY5=BY$3,BZ$3=BZ5),3,IF(AND(BY$3>BZ$3,BY5>BZ5),1,IF(AND(BY$3<BZ$3,BY5<BZ5),1,IF(AND(BY$3=BZ$3,BY5=BZ5),1,0))))) | CB5: 1 | CC5: 2 | CD5: =IF(OR(ISBLANK(CB5),ISBLANK(CC5),ISBLANK(CB$3)),"",IF(AND(CB5=CB$3,CC$3=CC5),3,IF(AND(CB$3>CC$3,CB5>CC5),1,IF(AND(CB$3<CC$3,CB5<CC5),1,IF(AND(CB$3=CC$3,CB5=CC5),1,0))))) | CE5: 2 | CF5: 1 | CG5: =IF(OR(ISBLANK(CE5),ISBLANK(CF5),ISBLANK(CE$3)),"",IF(AND(CE5=CE$3,CF$3=CF5),3,IF(AND(CE$3>CF$3,CE5>CF5),1,IF(AND(CE$3<CF$3,CE5<CF5),1,IF(AND(CE$3=CF$3,CE5=CF5),1,0))))) | CH5: 1 | CI5: 0 | CJ5: =IF(OR(ISBLANK(CH5),ISBLANK(CI5),ISBLANK(CH$3)),"",IF(AND(CH5=CH$3,CI$3=CI5),3,IF(AND(CH$3>CI$3,CH5>CI5),1,IF(AND(CH$3<CI$3,CH5<CI5),1,IF(AND(CH$3=CI$3,CH5=CI5),1,0))))) | CK5: 3 | CL5: 1 | CM5: =IF(OR(ISBLANK(CK5),ISBLANK(CL5),ISBLANK(CK$3)),"",IF(AND(CK5=CK$3,CL$3=CL5),3,IF(AND(CK$3>CL$3,CK5>CL5),1,IF(AND(CK$3<CL$3,CK5<CL5),1,IF(AND(CK$3=CL$3,CK5=CL5),1,0))))) | CN5: 0 | CO5: 1 | CP5: =IF(OR(ISBLANK(CN5),ISBLANK(CO5),ISBLANK(CN$3)),"",IF(AND(CN5=CN$3,CO$3=CO5),3,IF(AND(CN$3>CO$3,CN5>CO5),1,IF(AND(CN$3<CO$3,CN5<CO5),1,IF(AND(CN$3=CO$3,CN5=CO5),1,0))))) | CQ5: 4 | CR5: 1 | CS5: =IF(OR(ISBLANK(CQ5),ISBLANK(CR5),ISBLANK(CQ$3)),"",IF(AND(CQ5=CQ$3,CR$3=CR5),3,IF(AND(CQ$3>CR$3,CQ5>CR5),1,IF(AND(CQ$3<CR$3,CQ5<CR5),1,IF(AND(CQ$3=CR$3,CQ5=CR5),1,0))))) | CT5: 1 | CU5: 0 | CV5: =IF(OR(ISBLANK(CT5),ISBLANK(CU5),ISBLANK(CT$3)),"",IF(AND(CT5=CT$3,CU$3=CU5),3,IF(AND(CT$3>CU$3,CT5>CU5),1,IF(AND(CT$3<CU$3,CT5<CU5),1,IF(AND(CT$3=CU$3,CT5=CU5),1,0))))) | CW5: 2 | CX5: 1 | CY5: =IF(OR(ISBLANK(CW5),ISBLANK(CX5),ISBLANK(CW$3)),"",IF(AND(CW5=CW$3,CX$3=CX5),3,IF(AND(CW$3>CX$3,CW5>CX5),1,IF(AND(CW$3<CX$3,CW5<CX5),1,IF(AND(CW$3=CX$3,CW5=CX5),1,0))))) | CZ5: 4 | DA5: 1 | DB5: =IF(OR(ISBLANK(CZ5),ISBLANK(DA5),ISBLANK(CZ$3)),"",IF(AND(CZ5=CZ$3,DA$3=DA5),3,IF(AND(CZ$3>DA$3,CZ5>DA5),1,IF(AND(CZ$3<DA$3,CZ5<DA5),1,IF(AND(CZ$3=DA$3,CZ5=DA5),1,0))))) | DC5: 2 | DD5: 0 | DE5: =IF(OR(ISBLANK(DC5),ISBLANK(DD5),ISBLANK(DC$3)),"",IF(AND(DC5=DC$3,DD$3=DD5),3,IF(AND(DC$3>DD$3,DC5>DD5),1,IF(AND(DC$3<DD$3,DC5<DD5),1,IF(AND(DC$3=DD$3,DC5=DD5),1,0))))) | DF5: 1 | DG5: 2 | DH5: =IF(OR(ISBLANK(DF5),ISBLANK(DG5),ISBLANK(DF$3)),"",IF(AND(DF5=DF$3,DG$3=DG5),3,IF(AND(DF$3>DG$3,DF5>DG5),1,IF(AND(DF$3<DG$3,DF5<DG5),1,IF(AND(DF$3=DG$3,DF5=DG5),1,0))))) | DI5: 3 | DJ5: 0 | DK5: =IF(OR(ISBLANK(DI5),ISBLANK(DJ5),ISBLANK(DI$3)),"",IF(AND(DI5=DI$3,DJ$3=DJ5),3,IF(AND(DI$3>DJ$3,DI5>DJ5),1,IF(AND(DI$3<DJ$3,DI5<DJ5),1,IF(AND(DI$3=DJ$3,DI5=DJ5),1,0))))) | DL5: 2 | DM5: 1 | DN5: =IF(OR(ISBLANK(DL5),ISBLANK(DM5),ISBLANK(DL$3)),"",IF(AND(DL5=DL$3,DM$3=DM5),3,IF(AND(DL$3>DM$3,DL5>DM5),1,IF(AND(DL$3<DM$3,DL5<DM5),1,IF(AND(DL$3=DM$3,DL5=DM5),1,0))))) | DO5: 2 | DP5: 1 | DQ5: =IF(OR(ISBLANK(DO5),ISBLANK(DP5),ISBLANK(DO$3)),"",IF(AND(DO5=DO$3,DP$3=DP5),3,IF(AND(DO$3>DP$3,DO5>DP5),1,IF(AND(DO$3<DP$3,DO5<DP5),1,IF(AND(DO$3=DP$3,DO5=DP5),1,0))))) | DR5: 1 | DS5: 2 | DT5: =IF(OR(ISBLANK(DR5),ISBLANK(DS5),ISBLANK(DR$3)),"",IF(AND(DR5=DR$3,DS$3=DS5),3,IF(AND(DR$3>DS$3,DR5>DS5),1,IF(AND(DR$3<DS$3,DR5<DS5),1,IF(AND(DR$3=DS$3,DR5=DS5),1,0))))) | DU5: 3 | DV5: 1 | DW5: =IF(OR(ISBLANK(DU5),ISBLANK(DV5),ISBLANK(DU$3)),"",IF(AND(DU5=DU$3,DV$3=DV5),3,IF(AND(DU$3>DV$3,DU5>DV5),1,IF(AND(DU$3<DV$3,DU5<DV5),1,IF(AND(DU$3=DV$3,DU5=DV5),1,0))))) | DX5: 4 | DY5: 0 | DZ5: =IF(OR(ISBLANK(DX5),ISBLANK(DY5),ISBLANK(DX$3)),"",IF(AND(DX5=DX$3,DY$3=DY5),3,IF(AND(DX$3>DY$3,DX5>DY5),1,IF(AND(DX$3<DY$3,DX5<DY5),1,IF(AND(DX$3=DY$3,DX5=DY5),1,0))))) | EA5: 1 | EB5: 0 | EC5: =IF(OR(ISBLANK(EA5),ISBLANK(EB5),ISBLANK(EA$3)),"",IF(AND(EA5=EA$3,EB$3=EB5),3,IF(AND(EA$3>EB$3,EA5>EB5),1,IF(AND(EA$3<EB$3,EA5<EB5),1,IF(AND(EA$3=EB$3,EA5=EB5),1,0))))) | ED5: 0 | EE5: 1 | EF5: =IF(OR(ISBLANK(ED5),ISBLANK(EE5),ISBLANK(ED$3)),"",IF(AND(ED5=ED$3,EE$3=EE5),3,IF(AND(ED$3>EE$3,ED5>EE5),1,IF(AND(ED$3<EE$3,ED5<EE5),1,IF(AND(ED$3=EE$3,ED5=EE5),1,0))))) | EG5: 2 | EH5: 0 | EI5: =IF(OR(ISBLANK(EG5),ISBLANK(EH5),ISBLANK(EG$3)),"",IF(AND(EG5=EG$3,EH$3=EH5),3,IF(AND(EG$3>EH$3,EG5>EH5),1,IF(AND(EG$3<EH$3,EG5<EH5),1,IF(AND(EG$3=EH$3,EG5=EH5),1,0))))) | EJ5: 2 | EK5: 0 | EL5: =IF(OR(ISBLANK(EJ5),ISBLANK(EK5),ISBLANK(EJ$3)),"",IF(AND(EJ5=EJ$3,EK$3=EK5),3,IF(AND(EJ$3>EK$3,EJ5>EK5),1,IF(AND(EJ$3<EK$3,EJ5<EK5),1,IF(AND(EJ$3=EK$3,EJ5=EK5),1,0))))) | EM5: 0 | EN5: 2 | EO5: =IF(OR(ISBLANK(EM5),ISBLANK(EN5),ISBLANK(EM$3)),"",IF(AND(EM5=EM$3,EN$3=EN5),3,IF(AND(EM$3>EN$3,EM5>EN5),1,IF(AND(EM$3<EN$3,EM5<EN5),1,IF(AND(EM$3=EN$3,EM5=EN5),1,0))))) | EP5: 2 | EQ5: 1 | ER5: =IF(OR(ISBLANK(EP5),ISBLANK(EQ5),ISBLANK(EP$3)),"",IF(AND(EP5=EP$3,EQ$3=EQ5),3,IF(AND(EP$3>EQ$3,EP5>EQ5),1,IF(AND(EP$3<EQ$3,EP5<EQ5),1,IF(AND(EP$3=EQ$3,EP5=EQ5),1,0))))) | EU5: =IF(OR(ISBLANK(ES5),ISBLANK(ET5),ISBLANK(ES$3)),"",IF(AND(ES5=ES$3,ET$3=ET5),3,IF(AND(ES$3>ET$3,ES5>ET5),1,IF(AND(ES$3<ET$3,ES5<ET5),1,IF(AND(ES$3=ET$3,ES5=ET5),1,0))))) | EX5: =IF(OR(ISBLANK(EV5),ISBLANK(EW5),ISBLANK(EV$3)),"",IF(AND(EV5=EV$3,EW$3=EW5),3,IF(AND(EV$3>EW$3,EV5>EW5),1,IF(AND(EV$3<EW$3,EV5<EW5),1,IF(AND(EV$3=EW$3,EV5=EW5),1,0))))) | FA5: =IF(OR(ISBLANK(EY5),ISBLANK(EZ5),ISBLANK(EY$3)),"",IF(AND(EY5=EY$3,EZ$3=EZ5),3,IF(AND(EY$3>EZ$3,EY5>EZ5),1,IF(AND(EY$3<EZ$3,EY5<EZ5),1,IF(AND(EY$3=EZ$3,EY5=EZ5),1,0))))) | FD5: =IF(OR(ISBLANK(FB5),ISBLANK(FC5),ISBLANK(FB$3)),"",IF(AND(FB5=FB$3,FC$3=FC5),3,IF(AND(FB$3>FC$3,FB5>FC5),1,IF(AND(FB$3<FC$3,FB5<FC5),1,IF(AND(FB$3=FC$3,FB5=FC5),1,0))))) | FG5: =IF(OR(ISBLANK(FE5),ISBLANK(FF5),ISBLANK(FE$3)),"",IF(AND(FE5=FE$3,FF$3=FF5),3,IF(AND(FE$3>FF$3,FE5>FF5),1,IF(AND(FE$3<FF$3,FE5<FF5),1,IF(AND(FE$3=FF$3,FE5=FF5),1,0))))) | FJ5: =IF(OR(ISBLANK(FH5),ISBLANK(FI5),ISBLANK(FH$3)),"",IF(AND(FH5=FH$3,FI$3=FI5),3,IF(AND(FH$3>FI$3,FH5>FI5),1,IF(AND(FH$3<FI$3,FH5<FI5),1,IF(AND(FH$3=FI$3,FH5=FI5),1,0))))) | FM5: =IF(OR(ISBLANK(FK5),ISBLANK(FL5),ISBLANK(FK$3)),"",IF(AND(FK5=FK$3,FL$3=FL5),3,IF(AND(FK$3>FL$3,FK5>FL5),1,IF(AND(FK$3<FL$3,FK5<FL5),1,IF(AND(FK$3=FL$3,FK5=FL5),1,0))))) | FP5: =IF(OR(ISBLANK(FN5),ISBLANK(FO5),ISBLANK(FN$3)),"",IF(AND(FN5=FN$3,FO$3=FO5),3,IF(AND(FN$3>FO$3,FN5>FO5),1,IF(AND(FN$3<FO$3,FN5<FO5),1,IF(AND(FN$3=FO$3,FN5=FO5),1,0))))) | FS5: =IF(OR(ISBLANK(FQ5),ISBLANK(FR5),ISBLANK(FQ$3)),"",IF(AND(FQ5=FQ$3,FR$3=FR5),3,IF(AND(FQ$3>FR$3,FQ5>FR5),1,IF(AND(FQ$3<FR$3,FQ5<FR5),1,IF(AND(FQ$3=FR$3,FQ5=FR5),1,0))))) | FV5: =IF(OR(ISBLANK(FT5),ISBLANK(FU5),ISBLANK(FT$3)),"",IF(AND(FT5=FT$3,FU$3=FU5),3,IF(AND(FT$3>FU$3,FT5>FU5),1,IF(AND(FT$3<FU$3,FT5<FU5),1,IF(AND(FT$3=FU$3,FT5=FU5),1,0))))) | FY5: =IF(OR(ISBLANK(FW5),ISBLANK(FX5),ISBLANK(FW$3)),"",IF(AND(FW5=FW$3,FX$3=FX5),3,IF(AND(FW$3>FX$3,FW5>FX5),1,IF(AND(FW$3<FX$3,FW5<FX5),1,IF(AND(FW$3=FX$3,FW5=FX5),1,0))))) | GB5: =IF(OR(ISBLANK(FZ5),ISBLANK(GA5),ISBLANK(FZ$3)),"",IF(AND(FZ5=FZ$3,GA$3=GA5),3,IF(AND(FZ$3>GA$3,FZ5>GA5),1,IF(AND(FZ$3<GA$3,FZ5<GA5),1,IF(AND(FZ$3=GA$3,FZ5=GA5),1,0))))) | GE5: =IF(OR(ISBLANK(GC5),ISBLANK(GD5),ISBLANK(GC$3)),"",IF(AND(GC5=GC$3,GD$3=GD5),3,IF(AND(GC$3>GD$3,GC5>GD5),1,IF(AND(GC$3<GD$3,GC5<GD5),1,IF(AND(GC$3=GD$3,GC5=GD5),1,0))))) | GH5: =IF(OR(ISBLANK(GF5),ISBLANK(GG5),ISBLANK(GF$3)),"",IF(AND(GF5=GF$3,GG$3=GG5),3,IF(AND(GF$3>GG$3,GF5>GG5),1,IF(AND(GF$3<GG$3,GF5<GG5),1,IF(AND(GF$3=GG$3,GF5=GG5),1,0))))) | GK5: =IF(OR(ISBLANK(GI5),ISBLANK(GJ5),ISBLANK(GI$3)),"",IF(AND(GI5=GI$3,GJ$3=GJ5),3,IF(AND(GI$3>GJ$3,GI5>GJ5),1,IF(AND(GI$3<GJ$3,GI5<GJ5),1,IF(AND(GI$3=GJ$3,GI5=GJ5),1,0))))) | GN5: =IF(OR(ISBLANK(GL5),ISBLANK(GM5),ISBLANK(GL$3)),"",IF(AND(GL5=GL$3,GM$3=GM5),3,IF(AND(GL$3>GM$3,GL5>GM5),1,IF(AND(GL$3<GM$3,GL5<GM5),1,IF(AND(GL$3=GM$3,GL5=GM5),1,0))))) | GQ5: =IF(OR(ISBLANK(GO5),ISBLANK(GP5),ISBLANK(GO$3)),"",IF(AND(GO5=GO$3,GP$3=GP5),3,IF(AND(GO$3>GP$3,GO5>GP5),1,IF(AND(GO$3<GP$3,GO5<GP5),1,IF(AND(GO$3=GP$3,GO5=GP5),1,0))))) | GT5: =IF(OR(ISBLANK(GR5),ISBLANK(GS5),ISBLANK(GR$3)),"",IF(AND(GR5=GR$3,GS$3=GS5),3,IF(AND(GR$3>GS$3,GR5>GS5),1,IF(AND(GR$3<GS$3,GR5<GS5),1,IF(AND(GR$3=GS$3,GR5=GS5),1,0))))) | GW5: =IF(OR(ISBLANK(GU5),ISBLANK(GV5),ISBLANK(GU$3)),"",IF(AND(GU5=GU$3,GV$3=GV5),3,IF(AND(GU$3>GV$3,GU5>GV5),1,IF(AND(GU$3<GV$3,GU5<GV5),1,IF(AND(GU$3=GV$3,GU5=GV5),1,0))))) | GZ5: =IF(OR(ISBLANK(GX5),ISBLANK(GY5),ISBLANK(GX$3)),"",IF(AND(GX5=GX$3,GY$3=GY5),3,IF(AND(GX$3>GY$3,GX5>GY5),1,IF(AND(GX$3<GY$3,GX5<GY5),1,IF(AND(GX$3=GY$3,GX5=GY5),1,0))))) | HC5: =IF(OR(ISBLANK(HA5),ISBLANK(HB5),ISBLANK(HA$3)),"",IF(AND(HA5=HA$3,HB$3=HB5),3,IF(AND(HA$3>HB$3,HA5>HB5),1,IF(AND(HA$3<HB$3,HA5<HB5),1,IF(AND(HA$3=HB$3,HA5=HB5),1,0))))) | HF5: =IF(OR(ISBLANK(HD5),ISBLANK(HE5),ISBLANK(HD$3)),"",IF(AND(HD5=HD$3,HE$3=HE5),3,IF(AND(HD$3>HE$3,HD5>HE5),1,IF(AND(HD$3<HE$3,HD5<HE5),1,IF(AND(HD$3=HE$3,HD5=HE5),1,0))))) | HI5: =IF(OR(ISBLANK(HG5),ISBLANK(HH5),ISBLANK(HG$3)),"",IF(AND(HG5=HG$3,HH$3=HH5),3,IF(AND(HG$3>HH$3,HG5>HH5),1,IF(AND(HG$3<HH$3,HG5<HH5),1,IF(AND(HG$3=HH$3,HG5=HH5),1,0))))) | HL5: =IF(OR(ISBLANK(HJ5),ISBLANK(HK5),ISBLANK(HJ$3)),"",IF(AND(HJ5=HJ$3,HK$3=HK5),3,IF(AND(HJ$3>HK$3,HJ5>HK5),1,IF(AND(HJ$3<HK$3,HJ5<HK5),1,IF(AND(HJ$3=HK$3,HJ5=HK5),1,0))))) | HO5: =IF(OR(ISBLANK(HM5),ISBLANK(HN5),ISBLANK(HM$3)),"",IF(AND(HM5=HM$3,HN$3=HN5),3,IF(AND(HM$3>HN$3,HM5>HN5),1,IF(AND(HM$3<HN$3,HM5<HN5),1,IF(AND(HM$3=HN$3,HM5=HN5),1,0))))) | HR5: =IF(OR(ISBLANK(HP5),ISBLANK(HQ5),ISBLANK(HP$3)),"",IF(AND(HP5=HP$3,HQ$3=HQ5),3,IF(AND(HP$3>HQ$3,HP5>HQ5),1,IF(AND(HP$3<HQ$3,HP5<HQ5),1,IF(AND(HP$3=HQ$3,HP5=HQ5),1,0))))) | HU5: =IF(OR(ISBLANK(HS5),ISBLANK(HT5),ISBLANK(HS$3)),"",IF(AND(HS5=HS$3,HT$3=HT5),3,IF(AND(HS$3>HT$3,HS5>HT5),1,IF(AND(HS$3<HT$3,HS5<HT5),1,IF(AND(HS$3=HT$3,HS5=HT5),1,0))))) | HX5: =IF(OR(ISBLANK(HV5),ISBLANK(HW5),ISBLANK(HV$3)),"",IF(AND(HV5=HV$3,HW$3=HW5),3,IF(AND(HV$3>HW$3,HV5>HW5),1,IF(AND(HV$3<HW$3,HV5<HW5),1,IF(AND(HV$3=HW$3,HV5=HW5),1,0))))) | IA5: =IF(OR(ISBLANK(HY5),ISBLANK(HZ5),ISBLANK(HY$3)),"",IF(AND(HY5=HY$3,HZ$3=HZ5),3,IF(AND(HY$3>HZ$3,HY5>HZ5),1,IF(AND(HY$3<HZ$3,HY5<HZ5),1,IF(AND(HY$3=HZ$3,HY5=HZ5),1,0))))) | ID5: =IF(OR(ISBLANK(IB5),ISBLANK(IC5),ISBLANK(IB$3)),"",IF(AND(IB5=IB$3,IC$3=IC5),3,IF(AND(IB$3>IC$3,IB5>IC5),1,IF(AND(IB$3<IC$3,IB5<IC5),1,IF(AND(IB$3=IC$3,IB5=IC5),1,0))))) | IG5: =IF(OR(ISBLANK(IE5),ISBLANK(IF5),ISBLANK(IE$3)),"",IF(AND(IE5=IE$3,IF$3=IF5),3,IF(AND(IE$3>IF$3,IE5>IF5),1,IF(AND(IE$3<IF$3,IE5<IF5),1,IF(AND(IE$3=IF$3,IE5=IF5),1,0))))) | IJ5: =IF(OR(ISBLANK(IH5),ISBLANK(II5),ISBLANK(IH$3)),"",IF(AND(IH5=IH$3,II$3=II5),3,IF(AND(IH$3>II$3,IH5>II5),1,IF(AND(IH$3<II$3,IH5<II5),1,IF(AND(IH$3=II$3,IH5=II5),1,0))))) | IM5: =IF(OR(ISBLANK(IK5),ISBLANK(IL5),ISBLANK(IK$3)),"",IF(AND(IK5=IK$3,IL$3=IL5),3,IF(AND(IK$3>IL$3,IK5>IL5),1,IF(AND(IK$3<IL$3,IK5<IL5),1,IF(AND(IK$3=IL$3,IK5=IL5),1,0))))) | IP5: =IF(OR(ISBLANK(IN5),ISBLANK(IO5),ISBLANK(IN$3)),"",IF(AND(IN5=IN$3,IO$3=IO5),3,IF(AND(IN$3>IO$3,IN5>IO5),1,IF(AND(IN$3<IO$3,IN5<IO5),1,IF(AND(IN$3=IO$3,IN5=IO5),1,0))))) | IS5: =IF(OR(ISBLANK(IQ5),ISBLANK(IR5),ISBLANK(IQ$3)),"",IF(AND(IQ5=IQ$3,IR$3=IR5),3,IF(AND(IQ$3>IR$3,IQ5>IR5),1,IF(AND(IQ$3<IR$3,IQ5<IR5),1,IF(AND(IQ$3=IR$3,IQ5=IR5),1,0))))) | IV5: =IF(OR(ISBLANK(IT5),ISBLANK(IU5),ISBLANK(IT$3)),"",IF(AND(IT5=IT$3,IU$3=IU5),3,IF(AND(IT$3>IU$3,IT5>IU5),1,IF(AND(IT$3<IU$3,IT5<IU5),1,IF(AND(IT$3=IU$3,IT5=IU5),1,0))))) | IY5: =IF(OR(ISBLANK(IW5),ISBLANK(IX5),ISBLANK(IW$3)),"",IF(AND(IW5=IW$3,IX$3=IX5),3,IF(AND(IW$3>IX$3,IW5>IX5),1,IF(AND(IW$3<IX$3,IW5<IX5),1,IF(AND(IW$3=IX$3,IW5=IX5),1,0))))) | JB5: =IF(OR(ISBLANK(IZ5),ISBLANK(JA5),ISBLANK(IZ$3)),"",IF(AND(IZ5=IZ$3,JA$3=JA5),3,IF(AND(IZ$3>JA$3,IZ5>JA5),1,IF(AND(IZ$3<JA$3,IZ5<JA5),1,IF(AND(IZ$3=JA$3,IZ5=JA5),1,0))))) | JE5: =IF(OR(ISBLANK(JC5),ISBLANK(JD5),ISBLANK(JC$3)),"",IF(AND(JC5=JC$3,JD$3=JD5),3,IF(AND(JC$3>JD$3,JC5>JD5),1,IF(AND(JC$3<JD$3,JC5<JD5),1,IF(AND(JC$3=JD$3,JC5=JD5),1,0))))) | JH5: =IF(OR(ISBLANK(JF5),ISBLANK(JG5),ISBLANK(JF$3)),"",IF(AND(JF5=JF$3,JG$3=JG5),3,IF(AND(JF$3>JG$3,JF5>JG5),1,IF(AND(JF$3<JG$3,JF5<JG5),1,IF(AND(JF$3=JG$3,JF5=JG5),1,0))))) | JK5: =IF(OR(ISBLANK(JI5),ISBLANK(JJ5),ISBLANK(JI$3)),"",IF(AND(JI5=JI$3,JJ$3=JJ5),3,IF(AND(JI$3>JJ$3,JI5>JJ5),1,IF(AND(JI$3<JJ$3,JI5<JJ5),1,IF(AND(JI$3=JJ$3,JI5=JJ5),1,0))))) | JN5: =IF(OR(ISBLANK(JL5),ISBLANK(JM5),ISBLANK(JL$3)),"",IF(AND(JL5=JL$3,JM$3=JM5),3,IF(AND(JL$3>JM$3,JL5>JM5),1,IF(AND(JL$3<JM$3,JL5<JM5),1,IF(AND(JL$3=JM$3,JL5=JM5),1,0))))) | JQ5: =IF(OR(ISBLANK(JO5),ISBLANK(JP5),ISBLANK(JO$3)),"",IF(AND(JO5=JO$3,JP$3=JP5),3,IF(AND(JO$3>JP$3,JO5>JP5),1,IF(AND(JO$3<JP$3,JO5<JP5),1,IF(AND(JO$3=JP$3,JO5=JP5),1,0))))) | JT5: =IF(OR(ISBLANK(JR5),ISBLANK(JS5),ISBLANK(JR$3)),"",IF(AND(JR5=JR$3,JS$3=JS5),3,IF(AND(JR$3>JS$3,JR5>JS5),1,IF(AND(JR$3<JS$3,JR5<JS5),1,IF(AND(JR$3=JS$3,JR5=JS5),1,0))))) | JW5: =IF(OR(ISBLANK(JU5),ISBLANK(JV5),ISBLANK(JU$3)),"",IF(AND(JU5=JU$3,JV$3=JV5),3,IF(AND(JU$3>JV$3,JU5>JV5),1,IF(AND(JU$3<JV$3,JU5<JV5),1,IF(AND(JU$3=JV$3,JU5=JV5),1,0))))) | JZ5: =IF(OR(ISBLANK(JX5),ISBLANK(JY5),ISBLANK(JX$3)),"",IF(AND(JX5=JX$3,JY$3=JY5),3,IF(AND(JX$3>JY$3,JX5>JY5),1,IF(AND(JX$3<JY$3,JX5<JY5),1,IF(AND(JX$3=JY$3,JX5=JY5),1,0))))) | KC5: =IF(OR(ISBLANK(KA5),ISBLANK(KB5),ISBLANK(KA$3)),"",IF(AND(KA5=KA$3,KB$3=KB5),3,IF(AND(KA$3>KB$3,KA5>KB5),1,IF(AND(KA$3<KB$3,KA5<KB5),1,IF(AND(KA$3=KB$3,KA5=KB5),1,0))))) | KF5: =IF(OR(ISBLANK(KD5),ISBLANK(KE5),ISBLANK(KD$3)),"",IF(AND(KD5=KD$3,KE$3=KE5),3,IF(AND(KD$3>KE$3,KD5>KE5),1,IF(AND(KD$3<KE$3,KD5<KE5),1,IF(AND(KD$3=KE$3,KD5=KE5),1,0))))) | KI5: =IF(OR(ISBLANK(KG5),ISBLANK(KH5),ISBLANK(KG$3)),"",IF(AND(KG5=KG$3,KH$3=KH5),5,IF(AND(KG$3>KH$3,KG5>KH5),1,IF(AND(KG$3<KH$3,KG5<KH5),1,IF(AND(KG$3=KH$3,KG5=KH5),1,0))))) | KL5: =IF(OR(ISBLANK(KJ5),ISBLANK(KK5),ISBLANK(KJ$3)),"",IF(AND(KJ5=KJ$3,KK$3=KK5),5,IF(AND(KJ$3>KK$3,KJ5>KK5),1,IF(AND(KJ$3<KK$3,KJ5<KK5),1,IF(AND(KJ$3=KK$3,KJ5=KK5),1,0))))) | KO5: =IF(OR(ISBLANK(KM5),ISBLANK(KN5),ISBLANK(KM$3)),"",IF(AND(KM5=KM$3,KN$3=KN5),5,IF(AND(KM$3>KN$3,KM5>KN5),1,IF(AND(KM$3<KN$3,KM5<KN5),1,IF(AND(KM$3=KN$3,KM5=KN5),1,0))))) | KR5: =IF(OR(ISBLANK(KP5),ISBLANK(KQ5),ISBLANK(KP$3)),"",IF(AND(KP5=KP$3,KQ$3=KQ5),5,IF(AND(KP$3>KQ$3,KP5>KQ5),1,IF(AND(KP$3<KQ$3,KP5<KQ5),1,IF(AND(KP$3=KQ$3,KP5=KQ5),1,0))))) | KU5: =IF(OR(ISBLANK(KS5),ISBLANK(KT5),ISBLANK(KS$3)),"",IF(AND(KS5=KS$3,KT$3=KT5),5,IF(AND(KS$3>KT$3,KS5>KT5),1,IF(AND(KS$3<KT$3,KS5<KT5),1,IF(AND(KS$3=KT$3,KS5=KT5),1,0))))) | KX5: =IF(OR(ISBLANK(KV5),ISBLANK(KW5),ISBLANK(KV$3)),"",IF(AND(KV5=KV$3,KW$3=KW5),5,IF(AND(KV$3>KW$3,KV5>KW5),1,IF(AND(KV$3<KW$3,KV5<KW5),1,IF(AND(KV$3=KW$3,KV5=KW5),1,0))))) | LA5: =IF(OR(ISBLANK(KY5),ISBLANK(KZ5),ISBLANK(KY$3)),"",IF(AND(KY5=KY$3,KZ$3=KZ5),5,IF(AND(KY$3>KZ$3,KY5>KZ5),1,IF(AND(KY$3<KZ$3,KY5<KZ5),1,IF(AND(KY$3=KZ$3,KY5=KZ5),1,0))))) | LD5: =IF(OR(ISBLANK(LB5),ISBLANK(LC5),ISBLANK(LB$3)),"",IF(AND(LB5=LB$3,LC$3=LC5),5,IF(AND(LB$3>LC$3,LB5>LC5),1,IF(AND(LB$3<LC$3,LB5<LC5),1,IF(AND(LB$3=LC$3,LB5=LC5),1,0))))) | LF5: =IF(ISBLANK(LE5),"",IF(LE3=LE5,5,0)) | LH5: =IF(ISBLANK(LG5),"",IF(LG3=LG5,5,0)) | LJ5: =IF(ISBLANK(LI5),"",IF(LI3=LI5,5,0)) | LL5: =IF(ISBLANK(LK5),"",IF(LK3=LK5,5,0)) | LN5: =IF(ISBLANK(LM5),"",IF(LM3=LM5,5,0))
